<?xml version="1.0" ?>
<!-- =================================================================================== -->
<!-- |    This document was autogenerated by xacro from /home/workspace/robo-nd-projects/project_2/catkin_ws/src/my_robot/urdf/my_robot.xacro | -->
<!-- |    EDITING THIS FILE BY HAND IS NOT RECOMMENDED                                 | -->
<!-- =================================================================================== -->
<robot name="my_robot" xmlns:xacro="http://www.ros.org/wiki/xacro">
  <link name="robot_footprint"/>
  <joint name="robot_footprint_joint" type="fixed">
    <origin rpy="0 0 0" xyz="0 0 0"/>
    <parent link="robot_footprint"/>
    <child link="chassis"/>
  </joint>
  <link name="chassis">
    <origin rpy="0 0 0" xyz="0 0 0.1"/>
    <inertial>
      <mass value="15.0"/>
      <origin rpy="0 0 0" xyz="0.0 0 0"/>
      <inertia ixx="0.1" ixy="0" ixz="0" iyy="0.1" iyz="0" izz="0.1"/>
    </inertial>
    <collision name="collision">
      <origin rpy="0 0 0" xyz="0 0 0"/>
      <geometry>
        <box size=".4 .2 .1"/>
      </geometry>
    </collision>
    <visual name="chassis_visual">
      <origin rpy="0 0 0" xyz="0 0 0"/>
      <geometry>
        <box size=".4 .2 .1"/>
      </geometry>
    </visual>
    <collision name="back_caster_collision">
      <origin rpy="0 0 0" xyz="-0.15 0 -0.05"/>
      <geometry>
        <sphere radius="0.0499"/>
      </geometry>
    </collision>
    <visual name="back_caster_visual">
      <origin rpy="0 0 0" xyz="-0.15 0 -0.05"/>
      <geometry>
        <sphere radius="0.05"/>
      </geometry>
    </visual>
    <collision name="front_caster_collision">
      <origin rpy="0 0 0" xyz="0.15 0 -0.05"/>
      <geometry>
        <sphere radius="0.0499"/>
      </geometry>
    </collision>
    <visual name="front_caster_visual">
      <origin rpy="0 0 0" xyz="0.15 0 -0.05"/>
      <geometry>
        <sphere radius="0.05"/>
      </geometry>
    </visual>
  </link>
  <!-- Left Wheel -->
  <link name="left_wheel">
    <!-- Collision Element -->
    <collision>
      <geometry>
        <cylinder length="0.05" radius="0.1"/>
      </geometry>
      <origin rpy="0 1.5707 1.5707" xyz="0 0 0"/>
    </collision>
    <!-- Inertial Element -->
    <inertial>
      <mass value="5"/>
      <inertia ixx="0.1" ixy="0" ixz="0" iyy="0.1" iyz="0" izz="0.1"/>
    </inertial>
    <!-- Visual Element -->
    <visual>
      <geometry>
        <cylinder length="0.05" radius="0.1"/>
      </geometry>
      <origin rpy="0 1.5707 1.5707" xyz="0 0 0"/>
      <material name="grey"/>
    </visual>
  </link>
  <!-- Right Wheel -->
  <link name="right_wheel">
    <!-- Collision Element -->
    <collision>
      <geometry>
        <cylinder length="0.05" radius="0.1"/>
      </geometry>
      <origin rpy="0 1.5707 1.5707" xyz="0 0 0"/>
    </collision>
    <!-- Inertial Element -->
    <inertial>
      <mass value="5"/>
      <inertia ixx="0.1" ixy="0" ixz="0" iyy="0.1" iyz="0" izz="0.1"/>
    </inertial>
    <!-- Visual Element -->
    <visual>
      <geometry>
        <cylinder length="0.05" radius="0.1"/>
      </geometry>
      <origin rpy="0 1.5707 1.5707" xyz="0 0 0"/>
      <material name="grey"/>
    </visual>
  </link>
  <!-- Left Wheel Joint -->
  <joint name="left_wheel_hinge" type="continuous">
    <origin rpy="0 0 0" xyz="0 0.15 0"/>
    <child link="left_wheel"/>
    <parent link="chassis"/>
    <axis rpy="0 0 0" xyz="0 1 0"/>
    <limit effort="10" velocity="15"/>
    <dynamics damping="0.75" friction="0.7"/>
  </joint>
  <!-- Right Wheel Joint -->
  <joint name="right_wheel_hinge" type="continuous">
    <origin rpy="0 0 0" xyz="0 -0.15 0"/>
    <child link="right_wheel"/>
    <parent link="chassis"/>
    <axis rpy="0 0 0" xyz="0 1 0"/>
    <limit effort="10" velocity="15"/>
    <dynamics damping="0.75" friction="0.7"/>
  </joint>
  <!-- Camera sensor -->
  <link name="camera">
    <origin rpy="0 0 0" xyz="0 0 0"/>
    <inertial>
      <mass value="0.1"/>
      <origin rpy="0 0 0" xyz="0 0 0"/>
      <inertia ixx="1e-6" ixy="0" ixz="0" iyy="1e-6" iyz="0" izz="1e-6"/>
    </inertial>
    <collision>
      <origin rpy="0 0 0" xyz="0 0 0"/>
      <geometry>
        <box size="0.05 0.05 0.05"/>
      </geometry>
    </collision>
    <visual>
      <origin rpy="0 0 0" xyz="0 0 0"/>
      <geometry>
        <box size="0.05 0.05 0.05"/>
      </geometry>
    </visual>
  </link>
  <!-- Camera Joint -->
  <joint name="camera_joint" type="fixed">
    <origin rpy="0 0 0" xyz="0.2 0 0"/>
    <parent link="chassis"/>
    <child link="camera"/>
    <axis xyz="0 1 0"/>
  </joint>
  <!-- Hokuyo Link -->
  <link name="hokuyo">
    <!-- Collision Element: Box geometry for collision -->
    <collision>
      <geometry>
        <box size="0.1 0.1 0.1"/>
      </geometry>
      <origin rpy="0 0 0" xyz="0 0 0"/>
    </collision>
    <!-- Inertial Element: very small mass and inertia for the Hokuyo sensor -->
    <inertial>
      <mass value="1e-5"/>
      <inertia ixx="1e-6" ixy="0" ixz="0" iyy="1e-6" iyz="0" izz="1e-6"/>
    </inertial>
    <!-- Visual Element: Using a mesh for the Hokuyo sensor -->
    <visual>
      <geometry>
        <mesh filename="package://my_robot/meshes/hokuyo.dae"/>
      </geometry>
      <origin rpy="0 0 0" xyz="0 0 0"/>
    </visual>
  </link>
  <!-- Hokuyo Joint (Fixed joint to the chassis) -->
  <joint name="hokuyo_joint" type="fixed">
    <origin rpy="0 0 0" xyz="0.15 0 0.1"/>
    <parent link="chassis"/>
    <child link="hokuyo"/>
    <axis rpy="0 0 0" xyz="0 1 0"/>
  </joint>
</robot>

